Workbook

Sheet Notes
A1: Project I - data cleaning: lithium demand in India
A3: Grey headers = raw data as collected. Yellow headers = my cleaning formulas. Green = inputs I set.
A4: Sources for every row are on the Sources tab (Source_ID). A00 = my own assumption, explained next to it.
A6: What I fixed
A7: Trade (WITS / UN Comtrade, HS 283691 lithium carbonate and 282520 lithium hydroxide, 2018-2024):
A8: - numbers came as text with thousands separators and values in USD thousand: converted
A9: - the World total row sits in the same list as the partners: kept it only to reconcile
A10: - 16 rows have a unit value under 3 USD/kg, which no lithium chemical sells for. Ireland shows up every year
A11: at ~0.55 USD/kg; most likely a different product booked under 283691. Quantity re-estimated from value.
A12: - result: reported carbonate tonnes are about 2x the cleaned figure in most years
A13: - hydroxide converted at 0.880 t LCE per t LiOH.H2O so everything is in t LCE
A14: EV sales (6 reports, Vahan based):
... A22: The demand model itself is in Project_I_Lithium_Demand_Model.xlsx.

Sheet DQ_Log
A1: Table | B1: Issue | C1: Rows | D1: What I did
A2: Raw_Trade | B2: Numbers stored as text with separators | C2: =COUNTA(Raw_Trade!F2:F190) | D2: VALUE(SUBSTITUTE()), USD thousand to USD
A3: Raw_Trade | B3: World total rows mixed in with partners | C3: =COUNTIF(Raw_Trade!K2:K190,TRUE) | D3: Used only to reconcile (Trade_Summary col G = 0)
A4: Raw_Trade | B4: Unit value under the floor | C4: =COUNTIF(Raw_Trade!M2:M190,"Unit value below floor") | D4: Quantity re-estimated from value at the clean unit value
A5: Raw_Trade | B5: India as its own partner (re-import) | C5: =COUNTIF(Raw_Trade!M2:M190,"Re-import") | D5: Kept, flagged
A6: Trade_Summary | B6: Tonnes removed by cleaning | C6: =SUM(Trade_Summary!I2:I15)/1000 | D6: In tonnes; most of it is carbonate
A7: EV_Reported | B7: Segment labels needing a mapping | C7: =COUNTA(Lookups!A2:A37) | D7: Lookups tab
A8: EV_Reported | B8: Values with Indian grouping or words | C8: =SUMPRODUCT(--ISNUMBER(SEARCH("lakh",EV_Reported!D2:D51)))+SUMPRODUCT(--ISNUMBER(SEARCH("~",EV_Reported!D2:D51)))+SUMPRODUCT(--ISNUMBER(SEARCH(">",EV_Reported!D2:D51)))+SUMPRODUCT(--ISNUMBER(SEARCH("almost",EV_Reported!D2:D51)))+SUMPRODUCT(--(LEN(EV_Reported!D2:D51)-LEN(SUBSTITUTE(EV_Reported!D2:D51,",",""))=2)*(MID(EV_Reported!D2:D51,3,1)=",")) | D8: Parsed to numbers
A9: EV_Reported | B9: FY2025 total EVs: two sources disagree | C9: 2 | D9: Vahan retail (S07) for history; IESA CY2025 (S10) for the base year

Sheet Lookups
A1: Segment_As_Reported (lower case) | B1: Std_Segment | D1: Unit_As_Reported (lower case) | E1: Measure | G1: HS6 | H1: t_LCE_per_t_product | J1: Constant | K1: Value
A2: all vehicles | B2: All_Vehicles | D2: % of e-rickshaw market | E2: Share_LiIon_in_L3 | G2: 283691 | H2: 1 | J2: Unit value floor (USD/kg) | K2: 3
A3: battery demand | B3: Battery | D3: % of ev sales | E3: Share_of_EV_Sales | G3: 282520 | H3: 0.88 | J3: t LCE per t Li | K3: 5.323
A4: buses | B4: Bus | D4: % of gwh | E4: Share_of_EV_GWh | J4: Electrolyte kg LCE per kWh | K4: 0.012
A5: buses battery share | B5: Bus | D5: % of sales | E5: Target_Share_of_Sales | J5: Cell yield | K5: 0.92
A6: cars (4w) | B6: 4W | D6: % penetration | E6: EV_Penetration | J6: Li molar mass | K6: 6.941
A7: commercial cars | B7: 4W_Commercial | D7: % yoy growth | E7: YoY_Growth | J7: Fe | K7: 55.845
A8: e-2w | B8: 2W | D8: gwh | E8: GWh | J8: P | K8: 30.974
A9: e-2w (high-speed) | B9: 2W | D9: million | E9: Units | J9: O | K9: 15.999
A10: e-3w l5m | B10: 3W_L5 | D10: units | E10: Units | J10: Ni | K10: 58.693
A11: e-3w l5n | B11: 3W_L5 | D11: years | E11: Years | J11: Mn | K11: 54.938
A12: e-4w | B12: 4W | J12: Co | K12: 58.933
A13: e-cart | B13: 3W_L3
A14: e-rickshaw | B14: 3W_L3
A15: e-rickshaw li-ion battery life | B15: 3W_L3
A16: e-rickshaw li-ion share | B16: 3W_L3
A17: e2w | B17: 2W
A18: e3w passenger | B18: 3W_Passenger
A19: electric 2w | B19: 2W
A20: electric buses | B20: Bus
A21: electric commercial vehicles (buses, heavy and light goods) | B21: CV
A22: electric four-wheelers | B22: 4W
A23: electric passenger vehicles | B23: 4W
A24: electric passenger vehicles (cars, suvs, mpvs) | B24: 4W
... A37: two-wheelers battery share | B37: 2W

Sheet Raw_Trade
A1: Reporter | B1: Year | C1: HS6 | D1: Product | E1: Partner | F1: Trade_Value_USD_Thousand | G1: Quantity | H1: Quantity_Unit | I1: Value_USD | J1: Qty_kg | K1: Is_World_Row | L1: Unit_Value_USD_kg | M1: Flag | N1: Use_For_Ref | O1: Ref_Unit_Value | P1: Qty_Clean_kg | Q1: Qty_Clean_t_LCE
A2: India | B2: 2018 | C2: 283691 | D2: Lithium carbonates | E2: World | F2: 14,622.29 | G2: 1,656,320 | H2: Kg | I2: =VALUE(SUBSTITUTE(F2,",",""))*1000 | J2: =VALUE(SUBSTITUTE(G2,",","")) | K2: =E2="World" | L2: =IF(J2=0,0,I2/J2) | M2: =IF(K2,"",IF(E2="India","Re-import",IF(L2<Lookups!$K$2,"Unit value below floor",""))) | N2: =IF(AND(NOT(K2),M2=""),1,0) | O2: =SUMIFS($I$2:$I$190,$B$2:$B$190,B2,$C$2:$C$190,C2,$N$2:$N$190,1)/SUMIFS($J$2:$J$190,$B$2:$B$190,B2,$C$2:$C$190,C2,$N$2:$N$190,1) | P2: =IF(K2,"",IF(M2="Unit value below floor",I2/O2,J2)) | Q2: =IF(K2,"",P2/1000*VLOOKUP(C2,Lookups!$G$2:$H$3,2,FALSE))
A3: India | B3: 2018 | C3: 283691 | D3: Lithium carbonates | E3: United States | F3: 5,029.21 | G3: 124,803 | H3: Kg | I3: =VALUE(SUBSTITUTE(F3,",",""))*1000 | J3: =VALUE(SUBSTITUTE(G3,",","")) | K3: =E3="World" | L3: =IF(J3=0,0,I3/J3) | M3: =IF(K3,"",IF(E3="India","Re-import",IF(L3<Lookups!$K$2,"Unit value below floor",""))) | N3: =IF(AND(NOT(K3),M3=""),1,0) | O3: =SUMIFS($I$2:$I$190,$B$2:$B$190,B3,$C$2:$C$190,C3,$N$2:$N$190,1)/SUMIFS($J$2:$J$190,$B$2:$B$190,B3,$C$2:$C$190,C3,$N$2:$N$190,1) | P3: =IF(K3,"",IF(M3="Unit value below floor",I3/O3,J3)) | Q3: =IF(K3,"",P3/1000*VLOOKUP(C3,Lookups!$G$2:$H$3,2,FALSE))
A4: India | B4: 2018 | C4: 283691 | D4: Lithium carbonates | E4: Chile | F4: 4,042.80 | G4: 248,400 | H4: Kg | I4: =VALUE(SUBSTITUTE(F4,",",""))*1000 | J4: =VALUE(SUBSTITUTE(G4,",","")) | K4: =E4="World" | L4: =IF(J4=0,0,I4/J4) | M4: =IF(K4,"",IF(E4="India","Re-import",IF(L4<Lookups!$K$2,"Unit value below floor",""))) | N4: =IF(AND(NOT(K4),M4=""),1,0) | O4: =SUMIFS($I$2:$I$190,$B$2:$B$190,B4,$C$2:$C$190,C4,$N$2:$N$190,1)/SUMIFS($J$2:$J$190,$B$2:$B$190,B4,$C$2:$C$190,C4,$N$2:$N$190,1) | P4: =IF(K4,"",IF(M4="Unit value below floor",I4/O4,J4)) | Q4: =IF(K4,"",P4/1000*VLOOKUP(C4,Lookups!$G$2:$H$3,2,FALSE))
A5: India | B5: 2018 | C5: 283691 | D5: Lithium carbonates | E5: Belgium | F5: 1,954.25 | G5: 201,600 | H5: Kg | I5: =VALUE(SUBSTITUTE(F5,",",""))*1000 | J5: =VALUE(SUBSTITUTE(G5,",","")) | K5: =E5="World" | L5: =IF(J5=0,0,I5/J5) | M5: =IF(K5,"",IF(E5="India","Re-import",IF(L5<Lookups!$K$2,"Unit value below floor",""))) | N5: =IF(AND(NOT(K5),M5=""),1,0) | O5: =SUMIFS($I$2:$I$190,$B$2:$B$190,B5,$C$2:$C$190,C5,$N$2:$N$190,1)/SUMIFS($J$2:$J$190,$B$2:$B$190,B5,$C$2:$C$190,C5,$N$2:$N$190,1) | P5: =IF(K5,"",IF(M5="Unit value below floor",I5/O5,J5)) | Q5: =IF(K5,"",P5/1000*VLOOKUP(C5,Lookups!$G$2:$H$3,2,FALSE))
A6: India | B6: 2018 | C6: 283691 | D6: Lithium carbonates | E6: China | F6: 1,412.24 | G6: 115,533 | H6: Kg | I6: =VALUE(SUBSTITUTE(F6,",",""))*1000 | J6: =VALUE(SUBSTITUTE(G6,",","")) | K6: =E6="World" | L6: =IF(J6=0,0,I6/J6) | M6: =IF(K6,"",IF(E6="India","Re-import",IF(L6<Lookups!$K$2,"Unit value below floor",""))) | N6: =IF(AND(NOT(K6),M6=""),1,0) | O6: =SUMIFS($I$2:$I$190,$B$2:$B$190,B6,$C$2:$C$190,C6,$N$2:$N$190,1)/SUMIFS($J$2:$J$190,$B$2:$B$190,B6,$C$2:$C$190,C6,$N$2:$N$190,1) | P6: =IF(K6,"",IF(M6="Unit value below floor",I6/O6,J6)) | Q6: =IF(K6,"",P6/1000*VLOOKUP(C6,Lookups!$G$2:$H$3,2,FALSE))
A7: India | B7: 2018 | C7: 283691 | D7: Lithium carbonates | E7: Slovenia | F7: 518.36 | G7: 12,515 | H7: Kg | I7: =VALUE(SUBSTITUTE(F7,",",""))*1000 | J7: =VALUE(SUBSTITUTE(G7,",","")) | K7: =E7="World" | L7: =IF(J7=0,0,I7/J7) | M7: =IF(K7,"",IF(E7="India","Re-import",IF(L7<Lookups!$K$2,"Unit value below floor",""))) | N7: =IF(AND(NOT(K7),M7=""),1,0) | O7: =SUMIFS($I$2:$I$190,$B$2:$B$190,B7,$C$2:$C$190,C7,$N$2:$N$190,1)/SUMIFS($J$2:$J$190,$B$2:$B$190,B7,$C$2:$C$190,C7,$N$2:$N$190,1) | P7: =IF(K7,"",IF(M7="Unit value below floor",I7/O7,J7)) | Q7: =IF(K7,"",P7/1000*VLOOKUP(C7,Lookups!$G$2:$H$3,2,FALSE))
A8: India | B8: 2018 | C8: 283691 | D8: Lithium carbonates | E8: Argentina | F8: 467.65 | G8: 28,400 | H8: Kg | I8: =VALUE(SUBSTITUTE(F8,",",""))*1000 | J8: =VALUE(SUBSTITUTE(G8,",","")) | K8: =E8="World" | L8: =IF(J8=0,0,I8/J8) | M8: =IF(K8,"",IF(E8="India","Re-import",IF(L8<Lookups!$K$2,"Unit value below floor",""))) | N8: =IF(AND(NOT(K8),M8=""),1,0) | O8: =SUMIFS($I$2:$I$190,$B$2:$B$190,B8,$C$2:$C$190,C8,$N$2:$N$190,1)/SUMIFS($J$2:$J$190,$B$2:$B$190,B8,$C$2:$C$190,C8,$N$2:$N$190,1) | P8: =IF(K8,"",IF(M8="Unit value below floor",I8/O8,J8)) | Q8: =IF(K8,"",P8/1000*VLOOKUP(C8,Lookups!$G$2:$H$3,2,FALSE))
A9: India | B9: 2018 | C9: 283691 | D9: Lithium carbonates | E9: Austria | F9: 359.33 | G9: 9,500 | H9: Kg | I9: =VALUE(SUBSTITUTE(F9,",",""))*1000 | J9: =VALUE(SUBSTITUTE(G9,",","")) | K9: =E9="World" | L9: =IF(J9=0,0,I9/J9) | M9: =IF(K9,"",IF(E9="India","Re-import",IF(L9<Lookups!$K$2,"Unit value below floor",""))) | N9: =IF(AND(NOT(K9),M9=""),1,0) | O9: =SUMIFS($I$2:$I$190,$B$2:$B$190,B9,$C$2:$C$190,C9,$N$2:$N$190,1)/SUMIFS($J$2:$J$190,$B$2:$B$190,B9,$C$2:$C$190,C9,$N$2:$N$190,1) | P9: =IF(K9,"",IF(M9="Unit value below floor",I9/O9,J9)) | Q9: =IF(K9,"",P9/1000*VLOOKUP(C9,Lookups!$G$2:$H$3,2,FALSE))
A10: India | B10: 2018 | C10: 283691 | D10: Lithium carbonates | E10: Ireland | F10: 293.69 | G10: 540,000 | H10: Kg | I10: =VALUE(SUBSTITUTE(F10,",",""))*1000 | J10: =VALUE(SUBSTITUTE(G10,",","")) | K10: =E10="World" | L10: =IF(J10=0,0,I10/J10) | M10: =IF(K10,"",IF(E10="India","Re-import",IF(L10<Lookups!$K$2,"Unit value below floor",""))) | N10: =IF(AND(NOT(K10),M10=""),1,0) | O10: =SUMIFS($I$2:$I$190,$B$2:$B$190,B10,$C$2:$C$190,C10,$N$2:$N$190,1)/SUMIFS($J$2:$J$190,$B$2:$B$190,B10,$C$2:$C$190,C10,$N$2:$N$190,1) | P10: =IF(K10,"",IF(M10="Unit value below floor",I10/O10,J10)) | Q10: =IF(K10,"",P10/1000*VLOOKUP(C10,Lookups!$G$2:$H$3,2,FALSE))
A11: India | B11: 2018 | C11: 283691 | D11: Lithium carbonates | E11: United Kingdom | F11: 249.82 | G11: 150,001 | H11: Kg | I11: =VALUE(SUBSTITUTE(F11,",",""))*1000 | J11: =VALUE(SUBSTITUTE(G11,",","")) | K11: =E11="World" | L11: =IF(J11=0,0,I11/J11) | M11: =IF(K11,"",IF(E11="India","Re-import",IF(L11<Lookups!$K$2,"Unit value below floor",""))) | N11: =IF(AND(NOT(K11),M11=""),1,0) | O11: =SUMIFS($I$2:$I$190,$B$2:$B$190,B11,$C$2:$C$190,C11,$N$2:$N$190,1)/SUMIFS($J$2:$J$190,$B$2:$B$190,B11,$C$2:$C$190,C11,$N$2:$N$190,1) | P11: =IF(K11,"",IF(M11="Unit value below floor",I11/O11,J11)) | Q11: =IF(K11,"",P11/1000*VLOOKUP(C11,Lookups!$G$2:$H$3,2,FALSE))
A12: India | B12: 2018 | C12: 283691 | D12: Lithium carbonates | E12: Singapore | F12: 139.15 | G12: 3,531 | H12: Kg | I12: =VALUE(SUBSTITUTE(F12,",",""))*1000 | J12: =VALUE(SUBSTITUTE(G12,",","")) | K12: =E12="World" | L12: =IF(J12=0,0,I12/J12) | M12: =IF(K12,"",IF(E12="India","Re-import",IF(L12<Lookups!$K$2,"Unit value below floor",""))) | N12: =IF(AND(NOT(K12),M12=""),1,0) | O12: =SUMIFS($I$2:$I$190,$B$2:$B$190,B12,$C$2:$C$190,C12,$N$2:$N$190,1)/SUMIFS($J$2:$J$190,$B$2:$B$190,B12,$C$2:$C$190,C12,$N$2:$N$190,1) | P12: =IF(K12,"",IF(M12="Unit value below floor",I12/O12,J12)) | Q12: =IF(K12,"",P12/1000*VLOOKUP(C12,Lookups!$G$2:$H$3,2,FALSE))
A13: India | B13: 2018 | C13: 283691 | D13: Lithium carbonates | E13: France | F13: 118.96 | G13: 220,000 | H13: Kg | I13: =VALUE(SUBSTITUTE(F13,",",""))*1000 | J13: =VALUE(SUBSTITUTE(G13,",","")) | K13: =E13="World" | L13: =IF(J13=0,0,I13/J13) | M13: =IF(K13,"",IF(E13="India","Re-import",IF(L13<Lookups!$K$2,"Unit value below floor",""))) | N13: =IF(AND(NOT(K13),M13=""),1,0) | O13: =SUMIFS($I$2:$I$190,$B$2:$B$190,B13,$C$2:$C$190,C13,$N$2:$N$190,1)/SUMIFS($J$2:$J$190,$B$2:$B$190,B13,$C$2:$C$190,C13,$N$2:$N$190,1) | P13: =IF(K13,"",IF(M13="Unit value below floor",I13/O13,J13)) | Q13: =IF(K13,"",P13/1000*VLOOKUP(C13,Lookups!$G$2:$H$3,2,FALSE))
... A190: India | B190: 2024 | C190: 282520 | D190: Lithium oxide and hydroxide | E190: Australia | F190: 0.04 | G190: 3 | H190: Kg | I190: =VALUE(SUBSTITUTE(F190,",",""))*1000 | J190: =VALUE(SUBSTITUTE(G190,",","")) | K190: =E190="World" | L190: =IF(J190=0,0,I190/J190) | M190: =IF(K190,"",IF(E190="India","Re-import",IF(L190<Lookups!$K$2,"Unit value below floor",""))) | N190: =IF(AND(NOT(K190),M190=""),1,0) | O190: =SUMIFS($I$2:$I$190,$B$2:$B$190,B190,$C$2:$C$190,C190,$N$2:$N$190,1)/SUMIFS($J$2:$J$190,$B$2:$B$190,B190,$C$2:$C$190,C190,$N$2:$N$190,1) | P190: =IF(K190,"",IF(M190="Unit value below floor",I190/O190,J190)) | Q190: =IF(K190,"",P190/1000*VLOOKUP(C190,Lookups!$G$2:$H$3,2,FALSE))

Sheet Trade_Summary
A1: Year | B1: HS6 | C1: World_Value_USD | D1: Partner_Value_USD | E1: World_Qty_kg | F1: Partner_Qty_kg | G1: Check_Qty_Diff_kg | H1: Qty_Clean_kg | I1: Qty_Removed_kg | J1: Qty_Clean_t_LCE | K1: Clean_Unit_Value_USD_kg
A2: 2018 | B2: 283691 | C2: =SUMIFS(Raw_Trade!$I$2:$I$190,Raw_Trade!$B$2:$B$190,A2,Raw_Trade!$C$2:$C$190,B2,Raw_Trade!$K$2:$K$190,TRUE) | D2: =SUMIFS(Raw_Trade!$I$2:$I$190,Raw_Trade!$B$2:$B$190,A2,Raw_Trade!$C$2:$C$190,B2,Raw_Trade!$K$2:$K$190,FALSE) | E2: =SUMIFS(Raw_Trade!$J$2:$J$190,Raw_Trade!$B$2:$B$190,A2,Raw_Trade!$C$2:$C$190,B2,Raw_Trade!$K$2:$K$190,TRUE) | F2: =SUMIFS(Raw_Trade!$J$2:$J$190,Raw_Trade!$B$2:$B$190,A2,Raw_Trade!$C$2:$C$190,B2,Raw_Trade!$K$2:$K$190,FALSE) | G2: =E2-F2 | H2: =SUMIFS(Raw_Trade!$P$2:$P$190,Raw_Trade!$B$2:$B$190,A2,Raw_Trade!$C$2:$C$190,B2) | I2: =F2-H2 | J2: =SUMIFS(Raw_Trade!$Q$2:$Q$190,Raw_Trade!$B$2:$B$190,A2,Raw_Trade!$C$2:$C$190,B2) | K2: =D2/H2
A3: 2019 | B3: 283691 | C3: =SUMIFS(Raw_Trade!$I$2:$I$190,Raw_Trade!$B$2:$B$190,A3,Raw_Trade!$C$2:$C$190,B3,Raw_Trade!$K$2:$K$190,TRUE) | D3: =SUMIFS(Raw_Trade!$I$2:$I$190,Raw_Trade!$B$2:$B$190,A3,Raw_Trade!$C$2:$C$190,B3,Raw_Trade!$K$2:$K$190,FALSE) | E3: =SUMIFS(Raw_Trade!$J$2:$J$190,Raw_Trade!$B$2:$B$190,A3,Raw_Trade!$C$2:$C$190,B3,Raw_Trade!$K$2:$K$190,TRUE) | F3: =SUMIFS(Raw_Trade!$J$2:$J$190,Raw_Trade!$B$2:$B$190,A3,Raw_Trade!$C$2:$C$190,B3,Raw_Trade!$K$2:$K$190,FALSE) | G3: =E3-F3 | H3: =SUMIFS(Raw_Trade!$P$2:$P$190,Raw_Trade!$B$2:$B$190,A3,Raw_Trade!$C$2:$C$190,B3) | I3: =F3-H3 | J3: =SUMIFS(Raw_Trade!$Q$2:$Q$190,Raw_Trade!$B$2:$B$190,A3,Raw_Trade!$C$2:$C$190,B3) | K3: =D3/H3
A4: 2020 | B4: 283691 | C4: =SUMIFS(Raw_Trade!$I$2:$I$190,Raw_Trade!$B$2:$B$190,A4,Raw_Trade!$C$2:$C$190,B4,Raw_Trade!$K$2:$K$190,TRUE) | D4: =SUMIFS(Raw_Trade!$I$2:$I$190,Raw_Trade!$B$2:$B$190,A4,Raw_Trade!$C$2:$C$190,B4,Raw_Trade!$K$2:$K$190,FALSE) | E4: =SUMIFS(Raw_Trade!$J$2:$J$190,Raw_Trade!$B$2:$B$190,A4,Raw_Trade!$C$2:$C$190,B4,Raw_Trade!$K$2:$K$190,TRUE) | F4: =SUMIFS(Raw_Trade!$J$2:$J$190,Raw_Trade!$B$2:$B$190,A4,Raw_Trade!$C$2:$C$190,B4,Raw_Trade!$K$2:$K$190,FALSE) | G4: =E4-F4 | H4: =SUMIFS(Raw_Trade!$P$2:$P$190,Raw_Trade!$B$2:$B$190,A4,Raw_Trade!$C$2:$C$190,B4) | I4: =F4-H4 | J4: =SUMIFS(Raw_Trade!$Q$2:$Q$190,Raw_Trade!$B$2:$B$190,A4,Raw_Trade!$C$2:$C$190,B4) | K4: =D4/H4
A5: 2021 | B5: 283691 | C5: =SUMIFS(Raw_Trade!$I$2:$I$190,Raw_Trade!$B$2:$B$190,A5,Raw_Trade!$C$2:$C$190,B5,Raw_Trade!$K$2:$K$190,TRUE) | D5: =SUMIFS(Raw_Trade!$I$2:$I$190,Raw_Trade!$B$2:$B$190,A5,Raw_Trade!$C$2:$C$190,B5,Raw_Trade!$K$2:$K$190,FALSE) | E5: =SUMIFS(Raw_Trade!$J$2:$J$190,Raw_Trade!$B$2:$B$190,A5,Raw_Trade!$C$2:$C$190,B5,Raw_Trade!$K$2:$K$190,TRUE) | F5: =SUMIFS(Raw_Trade!$J$2:$J$190,Raw_Trade!$B$2:$B$190,A5,Raw_Trade!$C$2:$C$190,B5,Raw_Trade!$K$2:$K$190,FALSE) | G5: =E5-F5 | H5: =SUMIFS(Raw_Trade!$P$2:$P$190,Raw_Trade!$B$2:$B$190,A5,Raw_Trade!$C$2:$C$190,B5) | I5: =F5-H5 | J5: =SUMIFS(Raw_Trade!$Q$2:$Q$190,Raw_Trade!$B$2:$B$190,A5,Raw_Trade!$C$2:$C$190,B5) | K5: =D5/H5
A6: 2022 | B6: 283691 | C6: =SUMIFS(Raw_Trade!$I$2:$I$190,Raw_Trade!$B$2:$B$190,A6,Raw_Trade!$C$2:$C$190,B6,Raw_Trade!$K$2:$K$190,TRUE) | D6: =SUMIFS(Raw_Trade!$I$2:$I$190,Raw_Trade!$B$2:$B$190,A6,Raw_Trade!$C$2:$C$190,B6,Raw_Trade!$K$2:$K$190,FALSE) | E6: =SUMIFS(Raw_Trade!$J$2:$J$190,Raw_Trade!$B$2:$B$190,A6,Raw_Trade!$C$2:$C$190,B6,Raw_Trade!$K$2:$K$190,TRUE) | F6: =SUMIFS(Raw_Trade!$J$2:$J$190,Raw_Trade!$B$2:$B$190,A6,Raw_Trade!$C$2:$C$190,B6,Raw_Trade!$K$2:$K$190,FALSE) | G6: =E6-F6 | H6: =SUMIFS(Raw_Trade!$P$2:$P$190,Raw_Trade!$B$2:$B$190,A6,Raw_Trade!$C$2:$C$190,B6) | I6: =F6-H6 | J6: =SUMIFS(Raw_Trade!$Q$2:$Q$190,Raw_Trade!$B$2:$B$190,A6,Raw_Trade!$C$2:$C$190,B6) | K6: =D6/H6
A7: 2023 | B7: 283691 | C7: =SUMIFS(Raw_Trade!$I$2:$I$190,Raw_Trade!$B$2:$B$190,A7,Raw_Trade!$C$2:$C$190,B7,Raw_Trade!$K$2:$K$190,TRUE) | D7: =SUMIFS(Raw_Trade!$I$2:$I$190,Raw_Trade!$B$2:$B$190,A7,Raw_Trade!$C$2:$C$190,B7,Raw_Trade!$K$2:$K$190,FALSE) | E7: =SUMIFS(Raw_Trade!$J$2:$J$190,Raw_Trade!$B$2:$B$190,A7,Raw_Trade!$C$2:$C$190,B7,Raw_Trade!$K$2:$K$190,TRUE) | F7: =SUMIFS(Raw_Trade!$J$2:$J$190,Raw_Trade!$B$2:$B$190,A7,Raw_Trade!$C$2:$C$190,B7,Raw_Trade!$K$2:$K$190,FALSE) | G7: =E7-F7 | H7: =SUMIFS(Raw_Trade!$P$2:$P$190,Raw_Trade!$B$2:$B$190,A7,Raw_Trade!$C$2:$C$190,B7) | I7: =F7-H7 | J7: =SUMIFS(Raw_Trade!$Q$2:$Q$190,Raw_Trade!$B$2:$B$190,A7,Raw_Trade!$C$2:$C$190,B7) | K7: =D7/H7
A8: 2024 | B8: 283691 | C8: =SUMIFS(Raw_Trade!$I$2:$I$190,Raw_Trade!$B$2:$B$190,A8,Raw_Trade!$C$2:$C$190,B8,Raw_Trade!$K$2:$K$190,TRUE) | D8: =SUMIFS(Raw_Trade!$I$2:$I$190,Raw_Trade!$B$2:$B$190,A8,Raw_Trade!$C$2:$C$190,B8,Raw_Trade!$K$2:$K$190,FALSE) | E8: =SUMIFS(Raw_Trade!$J$2:$J$190,Raw_Trade!$B$2:$B$190,A8,Raw_Trade!$C$2:$C$190,B8,Raw_Trade!$K$2:$K$190,TRUE) | F8: =SUMIFS(Raw_Trade!$J$2:$J$190,Raw_Trade!$B$2:$B$190,A8,Raw_Trade!$C$2:$C$190,B8,Raw_Trade!$K$2:$K$190,FALSE) | G8: =E8-F8 | H8: =SUMIFS(Raw_Trade!$P$2:$P$190,Raw_Trade!$B$2:$B$190,A8,Raw_Trade!$C$2:$C$190,B8) | I8: =F8-H8 | J8: =SUMIFS(Raw_Trade!$Q$2:$Q$190,Raw_Trade!$B$2:$B$190,A8,Raw_Trade!$C$2:$C$190,B8) | K8: =D8/H8
A9: 2018 | B9: 282520 | C9: =SUMIFS(Raw_Trade!$I$2:$I$190,Raw_Trade!$B$2:$B$190,A9,Raw_Trade!$C$2:$C$190,B9,Raw_Trade!$K$2:$K$190,TRUE) | D9: =SUMIFS(Raw_Trade!$I$2:$I$190,Raw_Trade!$B$2:$B$190,A9,Raw_Trade!$C$2:$C$190,B9,Raw_Trade!$K$2:$K$190,FALSE) | E9: =SUMIFS(Raw_Trade!$J$2:$J$190,Raw_Trade!$B$2:$B$190,A9,Raw_Trade!$C$2:$C$190,B9,Raw_Trade!$K$2:$K$190,TRUE) | F9: =SUMIFS(Raw_Trade!$J$2:$J$190,Raw_Trade!$B$2:$B$190,A9,Raw_Trade!$C$2:$C$190,B9,Raw_Trade!$K$2:$K$190,FALSE) | G9: =E9-F9 | H9: =SUMIFS(Raw_Trade!$P$2:$P$190,Raw_Trade!$B$2:$B$190,A9,Raw_Trade!$C$2:$C$190,B9) | I9: =F9-H9 | J9: =SUMIFS(Raw_Trade!$Q$2:$Q$190,Raw_Trade!$B$2:$B$190,A9,Raw_Trade!$C$2:$C$190,B9) | K9: =D9/H9
A10: 2019 | B10: 282520 | C10: =SUMIFS(Raw_Trade!$I$2:$I$190,Raw_Trade!$B$2:$B$190,A10,Raw_Trade!$C$2:$C$190,B10,Raw_Trade!$K$2:$K$190,TRUE) | D10: =SUMIFS(Raw_Trade!$I$2:$I$190,Raw_Trade!$B$2:$B$190,A10,Raw_Trade!$C$2:$C$190,B10,Raw_Trade!$K$2:$K$190,FALSE) | E10: =SUMIFS(Raw_Trade!$J$2:$J$190,Raw_Trade!$B$2:$B$190,A10,Raw_Trade!$C$2:$C$190,B10,Raw_Trade!$K$2:$K$190,TRUE) | F10: =SUMIFS(Raw_Trade!$J$2:$J$190,Raw_Trade!$B$2:$B$190,A10,Raw_Trade!$C$2:$C$190,B10,Raw_Trade!$K$2:$K$190,FALSE) | G10: =E10-F10 | H10: =SUMIFS(Raw_Trade!$P$2:$P$190,Raw_Trade!$B$2:$B$190,A10,Raw_Trade!$C$2:$C$190,B10) | I10: =F10-H10 | J10: =SUMIFS(Raw_Trade!$Q$2:$Q$190,Raw_Trade!$B$2:$B$190,A10,Raw_Trade!$C$2:$C$190,B10) | K10: =D10/H10
A11: 2020 | B11: 282520 | C11: =SUMIFS(Raw_Trade!$I$2:$I$190,Raw_Trade!$B$2:$B$190,A11,Raw_Trade!$C$2:$C$190,B11,Raw_Trade!$K$2:$K$190,TRUE) | D11: =SUMIFS(Raw_Trade!$I$2:$I$190,Raw_Trade!$B$2:$B$190,A11,Raw_Trade!$C$2:$C$190,B11,Raw_Trade!$K$2:$K$190,FALSE) | E11: =SUMIFS(Raw_Trade!$J$2:$J$190,Raw_Trade!$B$2:$B$190,A11,Raw_Trade!$C$2:$C$190,B11,Raw_Trade!$K$2:$K$190,TRUE) | F11: =SUMIFS(Raw_Trade!$J$2:$J$190,Raw_Trade!$B$2:$B$190,A11,Raw_Trade!$C$2:$C$190,B11,Raw_Trade!$K$2:$K$190,FALSE) | G11: =E11-F11 | H11: =SUMIFS(Raw_Trade!$P$2:$P$190,Raw_Trade!$B$2:$B$190,A11,Raw_Trade!$C$2:$C$190,B11) | I11: =F11-H11 | J11: =SUMIFS(Raw_Trade!$Q$2:$Q$190,Raw_Trade!$B$2:$B$190,A11,Raw_Trade!$C$2:$C$190,B11) | K11: =D11/H11
A12: 2021 | B12: 282520 | C12: =SUMIFS(Raw_Trade!$I$2:$I$190,Raw_Trade!$B$2:$B$190,A12,Raw_Trade!$C$2:$C$190,B12,Raw_Trade!$K$2:$K$190,TRUE) | D12: =SUMIFS(Raw_Trade!$I$2:$I$190,Raw_Trade!$B$2:$B$190,A12,Raw_Trade!$C$2:$C$190,B12,Raw_Trade!$K$2:$K$190,FALSE) | E12: =SUMIFS(Raw_Trade!$J$2:$J$190,Raw_Trade!$B$2:$B$190,A12,Raw_Trade!$C$2:$C$190,B12,Raw_Trade!$K$2:$K$190,TRUE) | F12: =SUMIFS(Raw_Trade!$J$2:$J$190,Raw_Trade!$B$2:$B$190,A12,Raw_Trade!$C$2:$C$190,B12,Raw_Trade!$K$2:$K$190,FALSE) | G12: =E12-F12 | H12: =SUMIFS(Raw_Trade!$P$2:$P$190,Raw_Trade!$B$2:$B$190,A12,Raw_Trade!$C$2:$C$190,B12) | I12: =F12-H12 | J12: =SUMIFS(Raw_Trade!$Q$2:$Q$190,Raw_Trade!$B$2:$B$190,A12,Raw_Trade!$C$2:$C$190,B12) | K12: =D12/H12
A13: 2022 | B13: 282520 | C13: =SUMIFS(Raw_Trade!$I$2:$I$190,Raw_Trade!$B$2:$B$190,A13,Raw_Trade!$C$2:$C$190,B13,Raw_Trade!$K$2:$K$190,TRUE) | D13: =SUMIFS(Raw_Trade!$I$2:$I$190,Raw_Trade!$B$2:$B$190,A13,Raw_Trade!$C$2:$C$190,B13,Raw_Trade!$K$2:$K$190,FALSE) | E13: =SUMIFS(Raw_Trade!$J$2:$J$190,Raw_Trade!$B$2:$B$190,A13,Raw_Trade!$C$2:$C$190,B13,Raw_Trade!$K$2:$K$190,TRUE) | F13: =SUMIFS(Raw_Trade!$J$2:$J$190,Raw_Trade!$B$2:$B$190,A13,Raw_Trade!$C$2:$C$190,B13,Raw_Trade!$K$2:$K$190,FALSE) | G13: =E13-F13 | H13: =SUMIFS(Raw_Trade!$P$2:$P$190,Raw_Trade!$B$2:$B$190,A13,Raw_Trade!$C$2:$C$190,B13) | I13: =F13-H13 | J13: =SUMIFS(Raw_Trade!$Q$2:$Q$190,Raw_Trade!$B$2:$B$190,A13,Raw_Trade!$C$2:$C$190,B13) | K13: =D13/H13
... A15: 2024 | B15: 282520 | C15: =SUMIFS(Raw_Trade!$I$2:$I$190,Raw_Trade!$B$2:$B$190,A15,Raw_Trade!$C$2:$C$190,B15,Raw_Trade!$K$2:$K$190,TRUE) | D15: =SUMIFS(Raw_Trade!$I$2:$I$190,Raw_Trade!$B$2:$B$190,A15,Raw_Trade!$C$2:$C$190,B15,Raw_Trade!$K$2:$K$190,FALSE) | E15: =SUMIFS(Raw_Trade!$J$2:$J$190,Raw_Trade!$B$2:$B$190,A15,Raw_Trade!$C$2:$C$190,B15,Raw_Trade!$K$2:$K$190,TRUE) | F15: =SUMIFS(Raw_Trade!$J$2:$J$190,Raw_Trade!$B$2:$B$190,A15,Raw_Trade!$C$2:$C$190,B15,Raw_Trade!$K$2:$K$190,FALSE) | G15: =E15-F15 | H15: =SUMIFS(Raw_Trade!$P$2:$P$190,Raw_Trade!$B$2:$B$190,A15,Raw_Trade!$C$2:$C$190,B15) | I15: =F15-H15 | J15: =SUMIFS(Raw_Trade!$Q$2:$Q$190,Raw_Trade!$B$2:$B$190,A15,Raw_Trade!$C$2:$C$190,B15) | K15: =D15/H15
A17: Industrial baseline (avg 2022-24, t LCE)
A18: Carbonate (283691) | B18: =AVERAGEIFS(J2:J15,B2:B15,"283691",A2:A15,">=2022")
A19: Hydroxide (282520) | B19: =AVERAGEIFS(J2:J15,B2:B15,"282520",A2:A15,">=2022")

Sheet EV_Reported
A1: Source_ID | B1: Period_As_Reported | C1: Segment_As_Reported | D1: Value_As_Reported | E1: Unit_As_Reported | F1: Note | G1: Period | H1: Std_Segment | I1: Measure | J1: Value
A2: S07 | B2: FY2025 | C2: Total EVs | D2: 1,964,831 | E2: units | F2: Vahan retail | G2: =IF(LEFT(B2,2)="CY",B2,IF(ISNUMBER(SEARCH("target",B2)),"Target2030",IF(LEN(SUBSTITUTE(UPPER(B2)," ",""))=9,"FY"&MID(SUBSTITUTE(B2," ",""),3,2)&RIGHT(B2,2),SUBSTITUTE(UPPER(B2)," ","")))) | H2: =VLOOKUP(LOWER(TRIM(C2)),Lookups!$A$2:$B$37,2,FALSE) | I2: =VLOOKUP(LOWER(TRIM(E2)),Lookups!$D$2:$E$11,2,FALSE) | J2: =VALUE(TRIM(SUBSTITUTE(SUBSTITUTE(SUBSTITUTE(SUBSTITUTE(SUBSTITUTE(LOWER(D2),",",""),"~",""),">",""),"almost",""),"lakh","")))*IF(ISNUMBER(SEARCH("lakh",D2)),100000,1)*IF(LOWER(E2)="million",1000000,1)
A3: S07 | B3: FY2025 | C3: Electric two-wheelers (e2W) | D3: 1,149,307 | E3: units | G3: =IF(LEFT(B3,2)="CY",B3,IF(ISNUMBER(SEARCH("target",B3)),"Target2030",IF(LEN(SUBSTITUTE(UPPER(B3)," ",""))=9,"FY"&MID(SUBSTITUTE(B3," ",""),3,2)&RIGHT(B3,2),SUBSTITUTE(UPPER(B3)," ","")))) | H3: =VLOOKUP(LOWER(TRIM(C3)),Lookups!$A$2:$B$37,2,FALSE) | I3: =VLOOKUP(LOWER(TRIM(E3)),Lookups!$D$2:$E$11,2,FALSE) | J3: =VALUE(TRIM(SUBSTITUTE(SUBSTITUTE(SUBSTITUTE(SUBSTITUTE(SUBSTITUTE(LOWER(D3),",",""),"~",""),">",""),"almost",""),"lakh","")))*IF(ISNUMBER(SEARCH("lakh",D3)),100000,1)*IF(LOWER(E3)="million",1000000,1)
A4: S07 | B4: FY2025 | C4: Electric three-wheelers (e3W) | D4: 699,062 | E4: units | G4: =IF(LEFT(B4,2)="CY",B4,IF(ISNUMBER(SEARCH("target",B4)),"Target2030",IF(LEN(SUBSTITUTE(UPPER(B4)," ",""))=9,"FY"&MID(SUBSTITUTE(B4," ",""),3,2)&RIGHT(B4,2),SUBSTITUTE(UPPER(B4)," ","")))) | H4: =VLOOKUP(LOWER(TRIM(C4)),Lookups!$A$2:$B$37,2,FALSE) | I4: =VLOOKUP(LOWER(TRIM(E4)),Lookups!$D$2:$E$11,2,FALSE) | J4: =VALUE(TRIM(SUBSTITUTE(SUBSTITUTE(SUBSTITUTE(SUBSTITUTE(SUBSTITUTE(LOWER(D4),",",""),"~",""),">",""),"almost",""),"lakh","")))*IF(ISNUMBER(SEARCH("lakh",D4)),100000,1)*IF(LOWER(E4)="million",1000000,1)
A5: S07 | B5: FY2025 | C5: Electric passenger vehicles (cars, SUVs, MPVs) | D5: 107,462 | E5: units | G5: =IF(LEFT(B5,2)="CY",B5,IF(ISNUMBER(SEARCH("target",B5)),"Target2030",IF(LEN(SUBSTITUTE(UPPER(B5)," ",""))=9,"FY"&MID(SUBSTITUTE(B5," ",""),3,2)&RIGHT(B5,2),SUBSTITUTE(UPPER(B5)," ","")))) | H5: =VLOOKUP(LOWER(TRIM(C5)),Lookups!$A$2:$B$37,2,FALSE) | I5: =VLOOKUP(LOWER(TRIM(E5)),Lookups!$D$2:$E$11,2,FALSE) | J5: =VALUE(TRIM(SUBSTITUTE(SUBSTITUTE(SUBSTITUTE(SUBSTITUTE(SUBSTITUTE(LOWER(D5),",",""),"~",""),">",""),"almost",""),"lakh","")))*IF(ISNUMBER(SEARCH("lakh",D5)),100000,1)*IF(LOWER(E5)="million",1000000,1)
A6: S07 | B6: FY2025 | C6: Electric commercial vehicles (buses, heavy and light goods) | D6: 8,726 | E6: units | G6: =IF(LEFT(B6,2)="CY",B6,IF(ISNUMBER(SEARCH("target",B6)),"Target2030",IF(LEN(SUBSTITUTE(UPPER(B6)," ",""))=9,"FY"&MID(SUBSTITUTE(B6," ",""),3,2)&RIGHT(B6,2),SUBSTITUTE(UPPER(B6)," ","")))) | H6: =VLOOKUP(LOWER(TRIM(C6)),Lookups!$A$2:$B$37,2,FALSE) | I6: =VLOOKUP(LOWER(TRIM(E6)),Lookups!$D$2:$E$11,2,FALSE) | J6: =VALUE(TRIM(SUBSTITUTE(SUBSTITUTE(SUBSTITUTE(SUBSTITUTE(SUBSTITUTE(LOWER(D6),",",""),"~",""),">",""),"almost",""),"lakh","")))*IF(ISNUMBER(SEARCH("lakh",D6)),100000,1)*IF(LOWER(E6)="million",1000000,1)
A7: S07 | B7: FY2024 | C7: Total EVs | D7: 1,681,241 | E7: units | G7: =IF(LEFT(B7,2)="CY",B7,IF(ISNUMBER(SEARCH("target",B7)),"Target2030",IF(LEN(SUBSTITUTE(UPPER(B7)," ",""))=9,"FY"&MID(SUBSTITUTE(B7," ",""),3,2)&RIGHT(B7,2),SUBSTITUTE(UPPER(B7)," ","")))) | H7: =VLOOKUP(LOWER(TRIM(C7)),Lookups!$A$2:$B$37,2,FALSE) | I7: =VLOOKUP(LOWER(TRIM(E7)),Lookups!$D$2:$E$11,2,FALSE) | J7: =VALUE(TRIM(SUBSTITUTE(SUBSTITUTE(SUBSTITUTE(SUBSTITUTE(SUBSTITUTE(LOWER(D7),",",""),"~",""),">",""),"almost",""),"lakh","")))*IF(ISNUMBER(SEARCH("lakh",D7)),100000,1)*IF(LOWER(E7)="million",1000000,1)
A8: S07 | B8: FY2024 | C8: Electric three-wheelers (e3W) | D8: 632,798 | E8: units | G8: =IF(LEFT(B8,2)="CY",B8,IF(ISNUMBER(SEARCH("target",B8)),"Target2030",IF(LEN(SUBSTITUTE(UPPER(B8)," ",""))=9,"FY"&MID(SUBSTITUTE(B8," ",""),3,2)&RIGHT(B8,2),SUBSTITUTE(UPPER(B8)," ","")))) | H8: =VLOOKUP(LOWER(TRIM(C8)),Lookups!$A$2:$B$37,2,FALSE) | I8: =VLOOKUP(LOWER(TRIM(E8)),Lookups!$D$2:$E$11,2,FALSE) | J8: =VALUE(TRIM(SUBSTITUTE(SUBSTITUTE(SUBSTITUTE(SUBSTITUTE(SUBSTITUTE(LOWER(D8),",",""),"~",""),">",""),"almost",""),"lakh","")))*IF(ISNUMBER(SEARCH("lakh",D8)),100000,1)*IF(LOWER(E8)="million",1000000,1)
A9: S07 | B9: FY2024 | C9: Electric passenger vehicles | D9: 91,321 | E9: units | G9: =IF(LEFT(B9,2)="CY",B9,IF(ISNUMBER(SEARCH("target",B9)),"Target2030",IF(LEN(SUBSTITUTE(UPPER(B9)," ",""))=9,"FY"&MID(SUBSTITUTE(B9," ",""),3,2)&RIGHT(B9,2),SUBSTITUTE(UPPER(B9)," ","")))) | H9: =VLOOKUP(LOWER(TRIM(C9)),Lookups!$A$2:$B$37,2,FALSE) | I9: =VLOOKUP(LOWER(TRIM(E9)),Lookups!$D$2:$E$11,2,FALSE) | J9: =VALUE(TRIM(SUBSTITUTE(SUBSTITUTE(SUBSTITUTE(SUBSTITUTE(SUBSTITUTE(LOWER(D9),",",""),"~",""),">",""),"almost",""),"lakh","")))*IF(ISNUMBER(SEARCH("lakh",D9)),100000,1)*IF(LOWER(E9)="million",1000000,1)
A10: S07 | B10: FY2024 | C10: e2W | D10: 56 | E10: % of EV sales | F10: share only | G10: =IF(LEFT(B10,2)="CY",B10,IF(ISNUMBER(SEARCH("target",B10)),"Target2030",IF(LEN(SUBSTITUTE(UPPER(B10)," ",""))=9,"FY"&MID(SUBSTITUTE(B10," ",""),3,2)&RIGHT(B10,2),SUBSTITUTE(UPPER(B10)," ","")))) | H10: =VLOOKUP(LOWER(TRIM(C10)),Lookups!$A$2:$B$37,2,FALSE) | I10: =VLOOKUP(LOWER(TRIM(E10)),Lookups!$D$2:$E$11,2,FALSE) | J10: =VALUE(TRIM(SUBSTITUTE(SUBSTITUTE(SUBSTITUTE(SUBSTITUTE(SUBSTITUTE(LOWER(D10),",",""),"~",""),">",""),"almost",""),"lakh","")))*IF(ISNUMBER(SEARCH("lakh",D10)),100000,1)*IF(LOWER(E10)="million",1000000,1)
A11: S08 | B11: FY 2024-25 | C11: Total EV | D11: 20,37,831 | E11: units | F11: Indian digit grouping | G11: =IF(LEFT(B11,2)="CY",B11,IF(ISNUMBER(SEARCH("target",B11)),"Target2030",IF(LEN(SUBSTITUTE(UPPER(B11)," ",""))=9,"FY"&MID(SUBSTITUTE(B11," ",""),3,2)&RIGHT(B11,2),SUBSTITUTE(UPPER(B11)," ","")))) | H11: =VLOOKUP(LOWER(TRIM(C11)),Lookups!$A$2:$B$37,2,FALSE) | I11: =VLOOKUP(LOWER(TRIM(E11)),Lookups!$D$2:$E$11,2,FALSE) | J11: =VALUE(TRIM(SUBSTITUTE(SUBSTITUTE(SUBSTITUTE(SUBSTITUTE(SUBSTITUTE(LOWER(D11),",",""),"~",""),">",""),"almost",""),"lakh","")))*IF(ISNUMBER(SEARCH("lakh",D11)),100000,1)*IF(LOWER(E11)="million",1000000,1)
A12: S08 | B12: FY 2024-25 | C12: e-2W (high-speed) | D12: 12,09,772 | E12: units | G12: =IF(LEFT(B12,2)="CY",B12,IF(ISNUMBER(SEARCH("target",B12)),"Target2030",IF(LEN(SUBSTITUTE(UPPER(B12)," ",""))=9,"FY"&MID(SUBSTITUTE(B12," ",""),3,2)&RIGHT(B12,2),SUBSTITUTE(UPPER(B12)," ","")))) | H12: =VLOOKUP(LOWER(TRIM(C12)),Lookups!$A$2:$B$37,2,FALSE) | I12: =VLOOKUP(LOWER(TRIM(E12)),Lookups!$D$2:$E$11,2,FALSE) | J12: =VALUE(TRIM(SUBSTITUTE(SUBSTITUTE(SUBSTITUTE(SUBSTITUTE(SUBSTITUTE(LOWER(D12),",",""),"~",""),">",""),"almost",""),"lakh","")))*IF(ISNUMBER(SEARCH("lakh",D12)),100000,1)*IF(LOWER(E12)="million",1000000,1)
A13: S08 | B13: FY 2024-25 | C13: e-rickshaw | D13: 4,74,503 | E13: units | G13: =IF(LEFT(B13,2)="CY",B13,IF(ISNUMBER(SEARCH("target",B13)),"Target2030",IF(LEN(SUBSTITUTE(UPPER(B13)," ",""))=9,"FY"&MID(SUBSTITUTE(B13," ",""),3,2)&RIGHT(B13,2),SUBSTITUTE(UPPER(B13)," ","")))) | H13: =VLOOKUP(LOWER(TRIM(C13)),Lookups!$A$2:$B$37,2,FALSE) | I13: =VLOOKUP(LOWER(TRIM(E13)),Lookups!$D$2:$E$11,2,FALSE) | J13: =VALUE(TRIM(SUBSTITUTE(SUBSTITUTE(SUBSTITUTE(SUBSTITUTE(SUBSTITUTE(LOWER(D13),",",""),"~",""),">",""),"almost",""),"lakh","")))*IF(ISNUMBER(SEARCH("lakh",D13)),100000,1)*IF(LOWER(E13)="million",1000000,1)
A14: S08 | B14: FY 2024-25 | C14: e-cart | D14: 65,060 | E14: units | G14: =IF(LEFT(B14,2)="CY",B14,IF(ISNUMBER(SEARCH("target",B14)),"Target2030",IF(LEN(SUBSTITUTE(UPPER(B14)," ",""))=9,"FY"&MID(SUBSTITUTE(B14," ",""),3,2)&RIGHT(B14,2),SUBSTITUTE(UPPER(B14)," ","")))) | H14: =VLOOKUP(LOWER(TRIM(C14)),Lookups!$A$2:$B$37,2,FALSE) | I14: =VLOOKUP(LOWER(TRIM(E14)),Lookups!$D$2:$E$11,2,FALSE) | J14: =VALUE(TRIM(SUBSTITUTE(SUBSTITUTE(SUBSTITUTE(SUBSTITUTE(SUBSTITUTE(LOWER(D14),",",""),"~",""),">",""),"almost",""),"lakh","")))*IF(ISNUMBER(SEARCH("lakh",D14)),100000,1)*IF(LOWER(E14)="million",1000000,1)
A15: S08 | B15: FY 2024-25 | C15: e-4W | D15: 1,15,800 | E15: units | G15: =IF(LEFT(B15,2)="CY",B15,IF(ISNUMBER(SEARCH("target",B15)),"Target2030",IF(LEN(SUBSTITUTE(UPPER(B15)," ",""))=9,"FY"&MID(SUBSTITUTE(B15," ",""),3,2)&RIGHT(B15,2),SUBSTITUTE(UPPER(B15)," ","")))) | H15: =VLOOKUP(LOWER(TRIM(C15)),Lookups!$A$2:$B$37,2,FALSE) | I15: =VLOOKUP(LOWER(TRIM(E15)),Lookups!$D$2:$E$11,2,FALSE) | J15: =VALUE(TRIM(SUBSTITUTE(SUBSTITUTE(SUBSTITUTE(SUBSTITUTE(SUBSTITUTE(LOWER(D15),",",""),"~",""),">",""),"almost",""),"lakh","")))*IF(ISNUMBER(SEARCH("lakh",D15)),100000,1)*IF(LOWER(E15)="million",1000000,1)
A16: S08 | B16: FY 2023-24 | C16: Total EV | D16: 17,61,520 | E16: units | G16: =IF(LEFT(B16,2)="CY",B16,IF(ISNUMBER(SEARCH("target",B16)),"Target2030",IF(LEN(SUBSTITUTE(UPPER(B16)," ",""))=9,"FY"&MID(SUBSTITUTE(B16," ",""),3,2)&RIGHT(B16,2),SUBSTITUTE(UPPER(B16)," ","")))) | H16: =VLOOKUP(LOWER(TRIM(C16)),Lookups!$A$2:$B$37,2,FALSE) | I16: =VLOOKUP(LOWER(TRIM(E16)),Lookups!$D$2:$E$11,2,FALSE) | J16: =VALUE(TRIM(SUBSTITUTE(SUBSTITUTE(SUBSTITUTE(SUBSTITUTE(SUBSTITUTE(LOWER(D16),",",""),"~",""),">",""),"almost",""),"lakh","")))*IF(ISNUMBER(SEARCH("lakh",D16)),100000,1)*IF(LOWER(E16)="million",1000000,1)
A17: S08 | B17: FY 2022-23 | C17: Total EV | D17: 12,46,634 | E17: units | G17: =IF(LEFT(B17,2)="CY",B17,IF(ISNUMBER(SEARCH("target",B17)),"Target2030",IF(LEN(SUBSTITUTE(UPPER(B17)," ",""))=9,"FY"&MID(SUBSTITUTE(B17," ",""),3,2)&RIGHT(B17,2),SUBSTITUTE(UPPER(B17)," ","")))) | H17: =VLOOKUP(LOWER(TRIM(C17)),Lookups!$A$2:$B$37,2,FALSE) | I17: =VLOOKUP(LOWER(TRIM(E17)),Lookups!$D$2:$E$11,2,FALSE) | J17: =VALUE(TRIM(SUBSTITUTE(SUBSTITUTE(SUBSTITUTE(SUBSTITUTE(SUBSTITUTE(LOWER(D17),",",""),"~",""),">",""),"almost",""),"lakh","")))*IF(ISNUMBER(SEARCH("lakh",D17)),100000,1)*IF(LOWER(E17)="million",1000000,1)
A18: S08 | B18: FY 2024-25 | C18: e-3W L5M | D18: 6.6 | E18: % of EV sales | G18: =IF(LEFT(B18,2)="CY",B18,IF(ISNUMBER(SEARCH("target",B18)),"Target2030",IF(LEN(SUBSTITUTE(UPPER(B18)," ",""))=9,"FY"&MID(SUBSTITUTE(B18," ",""),3,2)&RIGHT(B18,2),SUBSTITUTE(UPPER(B18)," ","")))) | H18: =VLOOKUP(LOWER(TRIM(C18)),Lookups!$A$2:$B$37,2,FALSE) | I18: =VLOOKUP(LOWER(TRIM(E18)),Lookups!$D$2:$E$11,2,FALSE) | J18: =VALUE(TRIM(SUBSTITUTE(SUBSTITUTE(SUBSTITUTE(SUBSTITUTE(SUBSTITUTE(LOWER(D18),",",""),"~",""),">",""),"almost",""),"lakh","")))*IF(ISNUMBER(SEARCH("lakh",D18)),100000,1)*IF(LOWER(E18)="million",1000000,1)
A19: S08 | B19: FY 2024-25 | C19: e-2W | D19: 6.2 | E19: % penetration | F19: EV share of segment sales | G19: =IF(LEFT(B19,2)="CY",B19,IF(ISNUMBER(SEARCH("target",B19)),"Target2030",IF(LEN(SUBSTITUTE(UPPER(B19)," ",""))=9,"FY"&MID(SUBSTITUTE(B19," ",""),3,2)&RIGHT(B19,2),SUBSTITUTE(UPPER(B19)," ","")))) | H19: =VLOOKUP(LOWER(TRIM(C19)),Lookups!$A$2:$B$37,2,FALSE) | I19: =VLOOKUP(LOWER(TRIM(E19)),Lookups!$D$2:$E$11,2,FALSE) | J19: =VALUE(TRIM(SUBSTITUTE(SUBSTITUTE(SUBSTITUTE(SUBSTITUTE(SUBSTITUTE(LOWER(D19),",",""),"~",""),">",""),"almost",""),"lakh","")))*IF(ISNUMBER(SEARCH("lakh",D19)),100000,1)*IF(LOWER(E19)="million",1000000,1)
A20: S08 | B20: FY 2024-25 | C20: e-4W | D20: 2.7 | E20: % penetration | G20: =IF(LEFT(B20,2)="CY",B20,IF(ISNUMBER(SEARCH("target",B20)),"Target2030",IF(LEN(SUBSTITUTE(UPPER(B20)," ",""))=9,"FY"&MID(SUBSTITUTE(B20," ",""),3,2)&RIGHT(B20,2),SUBSTITUTE(UPPER(B20)," ","")))) | H20: =VLOOKUP(LOWER(TRIM(C20)),Lookups!$A$2:$B$37,2,FALSE) | I20: =VLOOKUP(LOWER(TRIM(E20)),Lookups!$D$2:$E$11,2,FALSE) | J20: =VALUE(TRIM(SUBSTITUTE(SUBSTITUTE(SUBSTITUTE(SUBSTITUTE(SUBSTITUTE(LOWER(D20),",",""),"~",""),">",""),"almost",""),"lakh","")))*IF(ISNUMBER(SEARCH("lakh",D20)),100000,1)*IF(LOWER(E20)="million",1000000,1)
A21: S08 | B21: FY 2024-25 | C21: e-3W L5M | D21: 22.8 | E21: % penetration | G21: =IF(LEFT(B21,2)="CY",B21,IF(ISNUMBER(SEARCH("target",B21)),"Target2030",IF(LEN(SUBSTITUTE(UPPER(B21)," ",""))=9,"FY"&MID(SUBSTITUTE(B21," ",""),3,2)&RIGHT(B21,2),SUBSTITUTE(UPPER(B21)," ","")))) | H21: =VLOOKUP(LOWER(TRIM(C21)),Lookups!$A$2:$B$37,2,FALSE) | I21: =VLOOKUP(LOWER(TRIM(E21)),Lookups!$D$2:$E$11,2,FALSE) | J21: =VALUE(TRIM(SUBSTITUTE(SUBSTITUTE(SUBSTITUTE(SUBSTITUTE(SUBSTITUTE(LOWER(D21),",",""),"~",""),">",""),"almost",""),"lakh","")))*IF(ISNUMBER(SEARCH("lakh",D21)),100000,1)*IF(LOWER(E21)="million",1000000,1)
A22: S08 | B22: FY 2024-25 | C22: e-3W L5N | D22: 21.5 | E22: % penetration | G22: =IF(LEFT(B22,2)="CY",B22,IF(ISNUMBER(SEARCH("target",B22)),"Target2030",IF(LEN(SUBSTITUTE(UPPER(B22)," ",""))=9,"FY"&MID(SUBSTITUTE(B22," ",""),3,2)&RIGHT(B22,2),SUBSTITUTE(UPPER(B22)," ","")))) | H22: =VLOOKUP(LOWER(TRIM(C22)),Lookups!$A$2:$B$37,2,FALSE) | I22: =VLOOKUP(LOWER(TRIM(E22)),Lookups!$D$2:$E$11,2,FALSE) | J22: =VALUE(TRIM(SUBSTITUTE(SUBSTITUTE(SUBSTITUTE(SUBSTITUTE(SUBSTITUTE(LOWER(D22),",",""),"~",""),">",""),"almost",""),"lakh","")))*IF(ISNUMBER(SEARCH("lakh",D22)),100000,1)*IF(LOWER(E22)="million",1000000,1)
A23: S08 | B23: FY 2024-25 | C23: Total EV | D23: 7.8 | E23: % penetration | G23: =IF(LEFT(B23,2)="CY",B23,IF(ISNUMBER(SEARCH("target",B23)),"Target2030",IF(LEN(SUBSTITUTE(UPPER(B23)," ",""))=9,"FY"&MID(SUBSTITUTE(B23," ",""),3,2)&RIGHT(B23,2),SUBSTITUTE(UPPER(B23)," ","")))) | H23: =VLOOKUP(LOWER(TRIM(C23)),Lookups!$A$2:$B$37,2,FALSE) | I23: =VLOOKUP(LOWER(TRIM(E23)),Lookups!$D$2:$E$11,2,FALSE) | J23: =VALUE(TRIM(SUBSTITUTE(SUBSTITUTE(SUBSTITUTE(SUBSTITUTE(SUBSTITUTE(LOWER(D23),",",""),"~",""),">",""),"almost",""),"lakh","")))*IF(ISNUMBER(SEARCH("lakh",D23)),100000,1)*IF(LOWER(E23)="million",1000000,1)
A24: S09 | B24: FY2026 | C24: Total EV | D24: >25 lakh | E24: units | F24: text says 'surpassed 25 lakh' | G24: =IF(LEFT(B24,2)="CY",B24,IF(ISNUMBER(SEARCH("target",B24)),"Target2030",IF(LEN(SUBSTITUTE(UPPER(B24)," ",""))=9,"FY"&MID(SUBSTITUTE(B24," ",""),3,2)&RIGHT(B24,2),SUBSTITUTE(UPPER(B24)," ","")))) | H24: =VLOOKUP(LOWER(TRIM(C24)),Lookups!$A$2:$B$37,2,FALSE) | I24: =VLOOKUP(LOWER(TRIM(E24)),Lookups!$D$2:$E$11,2,FALSE) | J24: =VALUE(TRIM(SUBSTITUTE(SUBSTITUTE(SUBSTITUTE(SUBSTITUTE(SUBSTITUTE(LOWER(D24),",",""),"~",""),">",""),"almost",""),"lakh","")))*IF(ISNUMBER(SEARCH("lakh",D24)),100000,1)*IF(LOWER(E24)="million",1000000,1)
A25: S09 | B25: FY2026 | C25: Electric 2W | D25: 57.8 | E25: % of EV sales | G25: =IF(LEFT(B25,2)="CY",B25,IF(ISNUMBER(SEARCH("target",B25)),"Target2030",IF(LEN(SUBSTITUTE(UPPER(B25)," ",""))=9,"FY"&MID(SUBSTITUTE(B25," ",""),3,2)&RIGHT(B25,2),SUBSTITUTE(UPPER(B25)," ","")))) | H25: =VLOOKUP(LOWER(TRIM(C25)),Lookups!$A$2:$B$37,2,FALSE) | I25: =VLOOKUP(LOWER(TRIM(E25)),Lookups!$D$2:$E$11,2,FALSE) | J25: =VALUE(TRIM(SUBSTITUTE(SUBSTITUTE(SUBSTITUTE(SUBSTITUTE(SUBSTITUTE(LOWER(D25),",",""),"~",""),">",""),"almost",""),"lakh","")))*IF(ISNUMBER(SEARCH("lakh",D25)),100000,1)*IF(LOWER(E25)="million",1000000,1)
A26: S09 | B26: FY2026 | C26: E3W passenger | D26: ~29 | E26: % of EV sales | G26: =IF(LEFT(B26,2)="CY",B26,IF(ISNUMBER(SEARCH("target",B26)),"Target2030",IF(LEN(SUBSTITUTE(UPPER(B26)," ",""))=9,"FY"&MID(SUBSTITUTE(B26," ",""),3,2)&RIGHT(B26,2),SUBSTITUTE(UPPER(B26)," ","")))) | H26: =VLOOKUP(LOWER(TRIM(C26)),Lookups!$A$2:$B$37,2,FALSE) | I26: =VLOOKUP(LOWER(TRIM(E26)),Lookups!$D$2:$E$11,2,FALSE) | J26: =VALUE(TRIM(SUBSTITUTE(SUBSTITUTE(SUBSTITUTE(SUBSTITUTE(SUBSTITUTE(LOWER(D26),",",""),"~",""),">",""),"almost",""),"lakh","")))*IF(ISNUMBER(SEARCH("lakh",D26)),100000,1)*IF(LOWER(E26)="million",1000000,1)
A27: S09 | B27: FY2026 | C27: Cars (4W) | D27: ~86 | E27: % YoY growth | G27: =IF(LEFT(B27,2)="CY",B27,IF(ISNUMBER(SEARCH("target",B27)),"Target2030",IF(LEN(SUBSTITUTE(UPPER(B27)," ",""))=9,"FY"&MID(SUBSTITUTE(B27," ",""),3,2)&RIGHT(B27,2),SUBSTITUTE(UPPER(B27)," ","")))) | H27: =VLOOKUP(LOWER(TRIM(C27)),Lookups!$A$2:$B$37,2,FALSE) | I27: =VLOOKUP(LOWER(TRIM(E27)),Lookups!$D$2:$E$11,2,FALSE) | J27: =VALUE(TRIM(SUBSTITUTE(SUBSTITUTE(SUBSTITUTE(SUBSTITUTE(SUBSTITUTE(LOWER(D27),",",""),"~",""),">",""),"almost",""),"lakh","")))*IF(ISNUMBER(SEARCH("lakh",D27)),100000,1)*IF(LOWER(E27)="million",1000000,1)
A28: S09 | B28: FY2026 | C28: Buses | D28: ~48 | E28: % YoY growth | G28: =IF(LEFT(B28,2)="CY",B28,IF(ISNUMBER(SEARCH("target",B28)),"Target2030",IF(LEN(SUBSTITUTE(UPPER(B28)," ",""))=9,"FY"&MID(SUBSTITUTE(B28," ",""),3,2)&RIGHT(B28,2),SUBSTITUTE(UPPER(B28)," ","")))) | H28: =VLOOKUP(LOWER(TRIM(C28)),Lookups!$A$2:$B$37,2,FALSE) | I28: =VLOOKUP(LOWER(TRIM(E28)),Lookups!$D$2:$E$11,2,FALSE) | J28: =VALUE(TRIM(SUBSTITUTE(SUBSTITUTE(SUBSTITUTE(SUBSTITUTE(SUBSTITUTE(LOWER(D28),",",""),"~",""),">",""),"almost",""),"lakh","")))*IF(ISNUMBER(SEARCH("lakh",D28)),100000,1)*IF(LOWER(E28)="million",1000000,1)
A29: S10 | B29: FY2025-26 | C29: Total EV | D29: 2.55 | E29: million | G29: =IF(LEFT(B29,2)="CY",B29,IF(ISNUMBER(SEARCH("target",B29)),"Target2030",IF(LEN(SUBSTITUTE(UPPER(B29)," ",""))=9,"FY"&MID(SUBSTITUTE(B29," ",""),3,2)&RIGHT(B29,2),SUBSTITUTE(UPPER(B29)," ","")))) | H29: =VLOOKUP(LOWER(TRIM(C29)),Lookups!$A$2:$B$37,2,FALSE) | I29: =VLOOKUP(LOWER(TRIM(E29)),Lookups!$D$2:$E$11,2,FALSE) | J29: =VALUE(TRIM(SUBSTITUTE(SUBSTITUTE(SUBSTITUTE(SUBSTITUTE(SUBSTITUTE(LOWER(D29),",",""),"~",""),">",""),"almost",""),"lakh","")))*IF(ISNUMBER(SEARCH("lakh",D29)),100000,1)*IF(LOWER(E29)="million",1000000,1)
A30: S10 | B30: FY2025-26 | C30: All vehicles | D30: 30.84 | E30: million | F30: total registrations | G30: =IF(LEFT(B30,2)="CY",B30,IF(ISNUMBER(SEARCH("target",B30)),"Target2030",IF(LEN(SUBSTITUTE(UPPER(B30)," ",""))=9,"FY"&MID(SUBSTITUTE(B30," ",""),3,2)&RIGHT(B30,2),SUBSTITUTE(UPPER(B30)," ","")))) | H30: =VLOOKUP(LOWER(TRIM(C30)),Lookups!$A$2:$B$37,2,FALSE) | I30: =VLOOKUP(LOWER(TRIM(E30)),Lookups!$D$2:$E$11,2,FALSE) | J30: =VALUE(TRIM(SUBSTITUTE(SUBSTITUTE(SUBSTITUTE(SUBSTITUTE(SUBSTITUTE(LOWER(D30),",",""),"~",""),">",""),"almost",""),"lakh","")))*IF(ISNUMBER(SEARCH("lakh",D30)),100000,1)*IF(LOWER(E30)="million",1000000,1)
A31: S10 | B31: CY2025 | C31: Total EV | D31: 2.6 | E31: million | F31: IESA/CES market report | G31: =IF(LEFT(B31,2)="CY",B31,IF(ISNUMBER(SEARCH("target",B31)),"Target2030",IF(LEN(SUBSTITUTE(UPPER(B31)," ",""))=9,"FY"&MID(SUBSTITUTE(B31," ",""),3,2)&RIGHT(B31,2),SUBSTITUTE(UPPER(B31)," ","")))) | H31: =VLOOKUP(LOWER(TRIM(C31)),Lookups!$A$2:$B$37,2,FALSE) | I31: =VLOOKUP(LOWER(TRIM(E31)),Lookups!$D$2:$E$11,2,FALSE) | J31: =VALUE(TRIM(SUBSTITUTE(SUBSTITUTE(SUBSTITUTE(SUBSTITUTE(SUBSTITUTE(LOWER(D31),",",""),"~",""),">",""),"almost",""),"lakh","")))*IF(ISNUMBER(SEARCH("lakh",D31)),100000,1)*IF(LOWER(E31)="million",1000000,1)
A32: S10 | B32: CY2024 | C32: Total EV | D32: 2.0 | E32: million | G32: =IF(LEFT(B32,2)="CY",B32,IF(ISNUMBER(SEARCH("target",B32)),"Target2030",IF(LEN(SUBSTITUTE(UPPER(B32)," ",""))=9,"FY"&MID(SUBSTITUTE(B32," ",""),3,2)&RIGHT(B32,2),SUBSTITUTE(UPPER(B32)," ","")))) | H32: =VLOOKUP(LOWER(TRIM(C32)),Lookups!$A$2:$B$37,2,FALSE) | I32: =VLOOKUP(LOWER(TRIM(E32)),Lookups!$D$2:$E$11,2,FALSE) | J32: =VALUE(TRIM(SUBSTITUTE(SUBSTITUTE(SUBSTITUTE(SUBSTITUTE(SUBSTITUTE(LOWER(D32),",",""),"~",""),">",""),"almost",""),"lakh","")))*IF(ISNUMBER(SEARCH("lakh",D32)),100000,1)*IF(LOWER(E32)="million",1000000,1)
A33: S10 | B33: CY2025 | C33: Electric two-wheelers | D33: 60.1 | E33: % of EV sales | G33: =IF(LEFT(B33,2)="CY",B33,IF(ISNUMBER(SEARCH("target",B33)),"Target2030",IF(LEN(SUBSTITUTE(UPPER(B33)," ",""))=9,"FY"&MID(SUBSTITUTE(B33," ",""),3,2)&RIGHT(B33,2),SUBSTITUTE(UPPER(B33)," ","")))) | H33: =VLOOKUP(LOWER(TRIM(C33)),Lookups!$A$2:$B$37,2,FALSE) | I33: =VLOOKUP(LOWER(TRIM(E33)),Lookups!$D$2:$E$11,2,FALSE) | J33: =VALUE(TRIM(SUBSTITUTE(SUBSTITUTE(SUBSTITUTE(SUBSTITUTE(SUBSTITUTE(LOWER(D33),",",""),"~",""),">",""),"almost",""),"lakh","")))*IF(ISNUMBER(SEARCH("lakh",D33)),100000,1)*IF(LOWER(E33)="million",1000000,1)
A34: S10 | B34: CY2025 | C34: Electric three-wheelers | D34: 31.6 | E34: % of EV sales | G34: =IF(LEFT(B34,2)="CY",B34,IF(ISNUMBER(SEARCH("target",B34)),"Target2030",IF(LEN(SUBSTITUTE(UPPER(B34)," ",""))=9,"FY"&MID(SUBSTITUTE(B34," ",""),3,2)&RIGHT(B34,2),SUBSTITUTE(UPPER(B34)," ","")))) | H34: =VLOOKUP(LOWER(TRIM(C34)),Lookups!$A$2:$B$37,2,FALSE) | I34: =VLOOKUP(LOWER(TRIM(E34)),Lookups!$D$2:$E$11,2,FALSE) | J34: =VALUE(TRIM(SUBSTITUTE(SUBSTITUTE(SUBSTITUTE(SUBSTITUTE(SUBSTITUTE(LOWER(D34),",",""),"~",""),">",""),"almost",""),"lakh","")))*IF(ISNUMBER(SEARCH("lakh",D34)),100000,1)*IF(LOWER(E34)="million",1000000,1)
A35: S10 | B35: CY2025 | C35: Electric four-wheelers | D35: 7.7 | E35: % of EV sales | G35: =IF(LEFT(B35,2)="CY",B35,IF(ISNUMBER(SEARCH("target",B35)),"Target2030",IF(LEN(SUBSTITUTE(UPPER(B35)," ",""))=9,"FY"&MID(SUBSTITUTE(B35," ",""),3,2)&RIGHT(B35,2),SUBSTITUTE(UPPER(B35)," ","")))) | H35: =VLOOKUP(LOWER(TRIM(C35)),Lookups!$A$2:$B$37,2,FALSE) | I35: =VLOOKUP(LOWER(TRIM(E35)),Lookups!$D$2:$E$11,2,FALSE) | J35: =VALUE(TRIM(SUBSTITUTE(SUBSTITUTE(SUBSTITUTE(SUBSTITUTE(SUBSTITUTE(LOWER(D35),",",""),"~",""),">",""),"almost",""),"lakh","")))*IF(ISNUMBER(SEARCH("lakh",D35)),100000,1)*IF(LOWER(E35)="million",1000000,1)
A36: S10 | B36: CY2025 | C36: Electric buses | D36: 0.2 | E36: % of EV sales | G36: =IF(LEFT(B36,2)="CY",B36,IF(ISNUMBER(SEARCH("target",B36)),"Target2030",IF(LEN(SUBSTITUTE(UPPER(B36)," ",""))=9,"FY"&MID(SUBSTITUTE(B36," ",""),3,2)&RIGHT(B36,2),SUBSTITUTE(UPPER(B36)," ","")))) | H36: =VLOOKUP(LOWER(TRIM(C36)),Lookups!$A$2:$B$37,2,FALSE) | I36: =VLOOKUP(LOWER(TRIM(E36)),Lookups!$D$2:$E$11,2,FALSE) | J36: =VALUE(TRIM(SUBSTITUTE(SUBSTITUTE(SUBSTITUTE(SUBSTITUTE(SUBSTITUTE(LOWER(D36),",",""),"~",""),">",""),"almost",""),"lakh","")))*IF(ISNUMBER(SEARCH("lakh",D36)),100000,1)*IF(LOWER(E36)="million",1000000,1)
A37: S10 | B37: CY2025 | C37: Electric trucks | D37: 0.4 | E37: % of EV sales | G37: =IF(LEFT(B37,2)="CY",B37,IF(ISNUMBER(SEARCH("target",B37)),"Target2030",IF(LEN(SUBSTITUTE(UPPER(B37)," ",""))=9,"FY"&MID(SUBSTITUTE(B37," ",""),3,2)&RIGHT(B37,2),SUBSTITUTE(UPPER(B37)," ","")))) | H37: =VLOOKUP(LOWER(TRIM(C37)),Lookups!$A$2:$B$37,2,FALSE) | I37: =VLOOKUP(LOWER(TRIM(E37)),Lookups!$D$2:$E$11,2,FALSE) | J37: =VALUE(TRIM(SUBSTITUTE(SUBSTITUTE(SUBSTITUTE(SUBSTITUTE(SUBSTITUTE(LOWER(D37),",",""),"~",""),">",""),"almost",""),"lakh","")))*IF(ISNUMBER(SEARCH("lakh",D37)),100000,1)*IF(LOWER(E37)="million",1000000,1)
A38: S10 | B38: CY2025 | C38: Battery demand | D38: 19 | E38: GWh | F38: all EV segments | G38: =IF(LEFT(B38,2)="CY",B38,IF(ISNUMBER(SEARCH("target",B38)),"Target2030",IF(LEN(SUBSTITUTE(UPPER(B38)," ",""))=9,"FY"&MID(SUBSTITUTE(B38," ",""),3,2)&RIGHT(B38,2),SUBSTITUTE(UPPER(B38)," ","")))) | H38: =VLOOKUP(LOWER(TRIM(C38)),Lookups!$A$2:$B$37,2,FALSE) | I38: =VLOOKUP(LOWER(TRIM(E38)),Lookups!$D$2:$E$11,2,FALSE) | J38: =VALUE(TRIM(SUBSTITUTE(SUBSTITUTE(SUBSTITUTE(SUBSTITUTE(SUBSTITUTE(LOWER(D38),",",""),"~",""),">",""),"almost",""),"lakh","")))*IF(ISNUMBER(SEARCH("lakh",D38)),100000,1)*IF(LOWER(E38)="million",1000000,1)
A39: S10 | B39: CY2024 | C39: Battery demand | D39: 13 | E39: GWh | G39: =IF(LEFT(B39,2)="CY",B39,IF(ISNUMBER(SEARCH("target",B39)),"Target2030",IF(LEN(SUBSTITUTE(UPPER(B39)," ",""))=9,"FY"&MID(SUBSTITUTE(B39," ",""),3,2)&RIGHT(B39,2),SUBSTITUTE(UPPER(B39)," ","")))) | H39: =VLOOKUP(LOWER(TRIM(C39)),Lookups!$A$2:$B$37,2,FALSE) | I39: =VLOOKUP(LOWER(TRIM(E39)),Lookups!$D$2:$E$11,2,FALSE) | J39: =VALUE(TRIM(SUBSTITUTE(SUBSTITUTE(SUBSTITUTE(SUBSTITUTE(SUBSTITUTE(LOWER(D39),",",""),"~",""),">",""),"almost",""),"lakh","")))*IF(ISNUMBER(SEARCH("lakh",D39)),100000,1)*IF(LOWER(E39)="million",1000000,1)
A40: S10 | B40: CY2025 | C40: Four-wheelers battery share | D40: 40 | E40: % of GWh | G40: =IF(LEFT(B40,2)="CY",B40,IF(ISNUMBER(SEARCH("target",B40)),"Target2030",IF(LEN(SUBSTITUTE(UPPER(B40)," ",""))=9,"FY"&MID(SUBSTITUTE(B40," ",""),3,2)&RIGHT(B40,2),SUBSTITUTE(UPPER(B40)," ","")))) | H40: =VLOOKUP(LOWER(TRIM(C40)),Lookups!$A$2:$B$37,2,FALSE) | I40: =VLOOKUP(LOWER(TRIM(E40)),Lookups!$D$2:$E$11,2,FALSE) | J40: =VALUE(TRIM(SUBSTITUTE(SUBSTITUTE(SUBSTITUTE(SUBSTITUTE(SUBSTITUTE(LOWER(D40),",",""),"~",""),">",""),"almost",""),"lakh","")))*IF(ISNUMBER(SEARCH("lakh",D40)),100000,1)*IF(LOWER(E40)="million",1000000,1)
...

Sheet Base_Year_2025
A1: CY2025 total EV sales (IESA, S10) | B1: =SUMIFS(EV_Reported!$J$2:$J$51,EV_Reported!$G$2:$G$51,"CY2025",EV_Reported!$H$2:$H$51,"Total",EV_Reported!$I$2:$I$51,"Units")
A2: Share of 3W EVs that are L3 (A00; FY2025 was 77%) | B2: 0.75
A4: Sub_Sector | B4: IESA_Segment | C4: Share_of_EV_Sales | D4: EV_Units_2025 | E4: EV_Penetration_2025 (input) | F4: Market_Units_2025 | G4: Note
A5: EV_2W | B5: 2W | C5: =SUMIFS(EV_Reported!$J$2:$J$51,EV_Reported!$G$2:$G$51,"CY2025",EV_Reported!$H$2:$H$51,B5,EV_Reported!$I$2:$I$51,"Share_of_EV_Sales")/100 | D5: =ROUND($B$1*C5,0) | E5: 0.078 | F5: =ROUND(D5/E5,-3) | G5: 2W penetration 6.2% in FY2025 (S08), rolled forward
A6: EV_3W_L5 | B6: 3W | C6: =SUMIFS(EV_Reported!$J$2:$J$51,EV_Reported!$G$2:$G$51,"CY2025",EV_Reported!$H$2:$H$51,B6,EV_Reported!$I$2:$I$51,"Share_of_EV_Sales")/100 | D6: =ROUND($B$1*C6*(1-$B$2),0) | E6: 0.25 | F6: =ROUND(D6/E6,-3) | G6: L5 penetration ~22% in FY2025 (S08)
A7: EV_3W_L3 | B7: 3W | C7: =SUMIFS(EV_Reported!$J$2:$J$51,EV_Reported!$G$2:$G$51,"CY2025",EV_Reported!$H$2:$H$51,B7,EV_Reported!$I$2:$I$51,"Share_of_EV_Sales")/100 | D7: =ROUND($B$1*C7*$B$2,0) | E7: 1 | F7: =ROUND(D7/E7,-3) | G7: L3 e-rickshaws and e-carts are all electric
A8: EV_4W | B8: 4W | C8: =SUMIFS(EV_Reported!$J$2:$J$51,EV_Reported!$G$2:$G$51,"CY2025",EV_Reported!$H$2:$H$51,B8,EV_Reported!$I$2:$I$51,"Share_of_EV_Sales")/100 | D8: =ROUND($B$1*C8,0) | E8: 0.045 | F8: =ROUND(D8/E8,-3) | G8: car penetration 2.7% in FY2025 and +86% sales in FY2026 (S08, S09)
A9: EV_Bus | B9: Bus | C9: =SUMIFS(EV_Reported!$J$2:$J$51,EV_Reported!$G$2:$G$51,"CY2025",EV_Reported!$H$2:$H$51,B9,EV_Reported!$I$2:$I$51,"Share_of_EV_Sales")/100 | D9: =ROUND($B$1*C9,0) | E9: 0.052 | F9: =ROUND(D9/E9,-3) | G9: A00
A10: EV_Truck | B10: Truck | C10: =SUMIFS(EV_Reported!$J$2:$J$51,EV_Reported!$G$2:$G$51,"CY2025",EV_Reported!$H$2:$H$51,B10,EV_Reported!$I$2:$I$51,"Share_of_EV_Sales")/100 | D10: =ROUND($B$1*C10,0) | E10: 0.011 | F10: =ROUND(D10/E10,-3) | G10: A00
A12: Calibration: battery GWh in 2025 at the model pack sizes vs IESA 19 GWh
A13: Sub_Sector | B13: kWh_per_Unit | C13: LiIon_Share | D13: GWh
A14: EV_2W | B14: 2.8 | C14: 1 | D14: =D5*B14*C14/1000000
A15: EV_3W_L5 | B15: 8 | C15: 1 | D15: =D6*B15*C15/1000000
A16: EV_3W_L3 | B16: 5 | C16: 0.25 | D16: =D7*B16*C16/1000000
A17: EV_4W | B17: 38 | C17: 1 | D17: =D8*B17*C17/1000000
A18: EV_Bus | B18: 280 | C18: 1 | D18: =D9*B18*C18/1000000
A19: EV_Truck | B19: 40 | C19: 1 | D19: =D10*B19*C19/1000000
A20: Model total | D20: =SUM(D14:D19)
A21: IESA reported (S10) | D21: =SUMIFS(EV_Reported!$J$2:$J$51,EV_Reported!$G$2:$G$51,"CY2025",EV_Reported!$H$2:$H$51,"Battery",EV_Reported!$I$2:$I$51,"GWh",EV_Reported!$A$2:$A$51,"S10")
A22: Model as share of IESA (rest is lead-acid L3 and pack-size spread) | D22: =D20/D21

Sheet Chemistry
A1: Chemistry | B1: Formula_Mass_g_mol | C1: Practical_Capacity_mAh_g | D1: Nominal_Voltage_V | E1: Wh_per_g_CAM | F1: kg_CAM_per_kWh | G1: Li_Mass_Fraction | H1: kg_Li_per_kWh_Cathode | I1: kg_LCE_per_kWh_Cell
A2: LFP LiFePO4 | B2: =Lookups!$K$6+Lookups!$K$7+Lookups!$K$8+4*Lookups!$K$9 | C2: 160 | D2: 3.2 | E2: =C2*D2/1000 | F2: =1/E2 | G2: =Lookups!$K$6/B2 | H2: =F2*G2 | I2: =(H2*Lookups!$K$3+Lookups!$K$4)/Lookups!$K$5
A3: NMC811 LiNi0.8Mn0.1Co0.1O2 | B3: =Lookups!$K$6+0.8*Lookups!$K$10+0.1*Lookups!$K$11+0.1*Lookups!$K$12+2*Lookups!$K$9 | C3: 195 | D3: 3.7 | E3: =C3*D3/1000 | F3: =1/E3 | G3: =Lookups!$K$6/B3 | H3: =F3*G3 | I3: =(H3*Lookups!$K$3+Lookups!$K$4)/Lookups!$K$5
A4: LCO LiCoO2 | B4: =Lookups!$K$6+Lookups!$K$12+2*Lookups!$K$9 | C4: 165 | D4: 3.85 | E4: =C4*D4/1000 | F4: =1/E4 | G4: =Lookups!$K$6/B4 | H4: =F4*G4 | I4: =(H4*Lookups!$K$3+Lookups!$K$4)/Lookups!$K$5
A5: Sodium-ion | I5: 0
A7: Lithium per kWh = kg of cathode per kWh x lithium mass fraction, converted to LCE, plus LiPF6 salt in the electrolyte, divided by cell yield (scrap). Check: IEA and BNEF quote roughly 0.5-0.7 kg LCE per kWh.

Sheet Industry_Baseline
A1: Sub_Sector | B1: Basis | C1: Share_Input | D1: t_LCE_2025
A2: IND_Grease | B2: Hydroxide imports x share to grease | C2: 0.9 | D2: =Trade_Summary!$B$19*C2
A3: IND_GlassCeramics | B3: Carbonate imports x share to glass and ceramics | C3: 0.5 | D3: =Trade_Summary!$B$18*C3
A4: IND_Pharma_Other | B4: Rest of carbonate and hydroxide | D4: =Trade_Summary!$B$18*(1-C3)+Trade_Summary!$B$19*(1-C2)
A6: Cross-check: grease survey (S26)
A7: India grease output 2020 (t) = 190m lb x 0.4536 | B7: =190000000*0.4536/1000
A8: Lithium-thickened share | B8: 0.85
A9: LiOH.H2O in lithium soap grease (typical) | B9: 0.016
A10: Implied t LCE (survey covers 16 of 31 makers) | B10: =B7*B8*B9*Lookups!$H$3
A11: Model grease baseline (t LCE) | B11: =D2

Sheet Sources
A1: Source_ID | B1: Publisher | C1: Title | D1: Year | E1: URL | F1: Accessed
A2: S01 | B2: USGS | C2: Mineral Commodity Summaries 2026: Lithium | D2: 2026 | E2: https://pubs.usgs.gov/periodicals/mcs2026/mcs2026-lithium.pdf | F2: 2026-10-10
A3: S02 | B3: Lok Sabha (Ministry of Mines) | C3: Unstarred Question No. 267 on lithium in J&K (answered 24 Jul 2024) | D3: 2024 | E3: https://eparlib.nic.in/bitstream/123456789/2980749/1/AU267_CULiB1.pdf | F3: 2026-10-10
A4: S03 | B4: CEEW | C4: Making India a Hub for Critical Minerals Processing (Kumar; Chandhok; Jain) | D4: 2025 | E4: https://www.ceew.in/node/4672 | F4: 2026-10-10
A5: S04 | B5: CEEW; CSEP; ICRIER; IISD; Shakti | C5: State of the Sector: Critical Energy Transition Minerals for India Vol. I | D5: 2025 | E5: https://www.ceew.in/node/4306 | F5: 2026-10-10
A6: S05 | B6: CEEW; CSEP; ICRIER; IISD; Shakti | C6: State of the Sector: Critical Energy Transition Minerals for India Vol. II | D6: 2025 | E6: https://www.ceew.in/sites/default/files/state-of-the-sector-cetms-for-india-vol-ii.pdf | F6: 2026-10-10
A7: S06 | B7: World Bank WITS (UN Comtrade) | C7: India imports by partner: HS 283691 and 282520 | D7: 2026 | E7: https://wits.worldbank.org/trade/comtrade/en/country/IND/year/2023/tradeflow/Imports/partner/ALL/product/283691 | F7: 2026-10-10
A8: S07 | B8: Autocar Professional (Vahan data) | C8: EV sales grow 17% to 1.96 million in FY2025 | D8: 2025 | E8: https://autocarpro.in/analysis-sales/ev-sales-grow-17-to-196-million-in-fy2025-2-and-3ws-cars-and-suvs-hit-new-highs-125656 | F8: 2026-10-10
A9: S08 | B9: EVreporter | C9: India EV Report FY 2024-25 (excerpts) | D9: 2025 | E9: https://evreporter.com/evreporter-india-ev-report-fy-2024-25-excerpts/ | F9: 2026-10-10
A10: S09 | B10: JMK Research | C10: Annual India EV Report Card FY2026 | D10: 2026 | E10: https://jmkresearch.com/annual-india-ev-report-card-fy2026/ | F10: 2026-10-10
A11: S10 | B11: IESA via EV Infrastructure News | C11: India registered 2.55 million EV sales in FY2025-26 | D11: 2026 | E11: https://www.evinfrastructurenews.com/emobility/india-registers-2-55-million-ev-sales-in-fy2025-26-says-iesa | F11: 2026-10-10
A12: S11 | B12: CEA via Powerline | C12: National Electricity Plan (Generation) 2022-32 | D12: 2023 | E12: https://powerline.net.in/2023/07/03/green-roadmap-cea-prioritises-renewables-in-the-national-electricity-plan/ | F12: 2026-10-10
A13: S12 | B13: Powerline | C13: Growing Pipeline: battery storage market moves towards larger-scale deployment | D13: 2026 | E13: https://powerline.net.in/2026/07/24/growing-pipeline-battery-storage-market-moves-towards-larger-scale-deployment/ | F13: 2026-10-10
... A32: S31 | B32: EVreporter | C32: Lithium deposits found in J&K: what to make of the discovery? | D32: 2023 | E32: https://evreporter.com/lithium-deposits-found-in-jk-what-to-make-of-the-discovery/ | F32: 2026-10-10
A33: A00 | B33: Project I author | C33: Modelling assumption (see Assumptions sheet for reasoning) | D33: 2026 | F33: 2026-10-10
